Workbook

Sheet in
A1: customer_id
A2: 154536156 | B2: 44805 | D2: 39 | E2: month | F2: Yes
A3: 149713408 | B3: 44805 | C3: 44806 | D3: 39 | E3: month | F3: No
A4: 153756284 | B4: 44805 | C4: 44806 | D4: 39 | E4: month | F4: No
A5: 121253113 | B5: 44805 | C5: 44827 | D5: 39 | E5: month | F5: Yes
A6: 154467210 | B6: 44805 | C6: 45106 | D6: 39 | E6: month | F6: Yes
A7: 154510811 | B7: 44805 | C7: 45054 | D7: 39 | E7: month | F7: Yes
A8: 154494346 | B8: 44805 | C8: 44891 | D8: 39 | E8: month | F8: Yes
A9: 148671505 | B9: 44805 | C9: 44888 | D9: 39 | E9: month | F9: Yes
A10: 154568379 | B10: 44805 | C10: 44859 | D10: 39 | E10: month | F10: Yes
A11: 154428434 | B11: 44805 | C11: 44865 | D11: 39 | E11: month | F11: Yes
A12: 154601651 | B12: 44805 | C12: 44830 | D12: 39 | E12: month | F12: Yes
A13: 122824692 | B13: 44805 | C13: 44819 | D13: 39 | E13: month | F13: Yes
A14: 152925600 | B14: 44806 | D14: 39 | E14: month | F14: Yes
A15: 151154171 | B15: 44806 | C15: 44806 | D15: 39 | E15: month | F15: Yes
A16: 154640950 | B16: 44806 | C16: 44904 | D16: 39 | E16: month | F16: Yes
A17: 154617329 | B17: 44806 | C17: 44861 | D17: 39 | E17: month | F17: Yes
A18: 154089211 | B18: 44806 | C18: 44843 | D18: 39 | E18: month | F18: Yes
A19: 154653820 | B19: 44806 | C19: 44830 | D19: 39 | E19: month | F19: Yes
A20: 154131290 | B20: 44807 | D20: 39 | E20: month | F20: Yes
A21: 154434009 | B21: 44807 | D21: 39 | E21: month | F21: Yes
A22: 136108848 | B22: 44807 | C22: 44808 | D22: 39 | E22: month | F22: Yes
A23: 135185873 | B23: 44807 | C23: 45056 | D23: 39 | E23: month | F23: Yes
A24: 154592664 | B24: 44807 | C24: 45017 | D24: 39 | E24: month | F24: Yes
A25: 119436804 | B25: 44807 | C25: 45026 | D25: 39 | E25: month | F25: Yes
A26: 152929657 | B26: 44807 | C26: 44888 | D26: 39 | E26: month | F26: Yes
A27: 154708974 | B27: 44807 | C27: 44852 | D27: 39 | E27: month | F27: Yes
A28: 154567722 | B28: 44807 | C28: 44833 | D28: 39 | E28: month | F28: Yes
A29: 154719788 | B29: 44807 | C29: 44829 | D29: 39 | E29: month | F29: Yes
A30: 154809306 | B30: 44808 | C30: 44809 | D30: 39 | E30: month | F30: Yes
A31: 140391539 | B31: 44808 | C31: 45021 | D31: 39 | E31: month | F31: Yes
A32: 153194806 | B32: 44808 | C32: 45032 | D32: 39 | E32: month | F32: Yes
A33: 144402204 | B33: 44808 | C33: 44826 | D33: 39 | E33: month | F33: Yes
... A38: 153368891 | B38: 44808 | C38: 44845 | D38: 39 | E38: month | F38: Yes
A39: 154225450 | B39: 44809 | D39: 39 | E39: month | F39: Yes
A40: 154904040 | B40: 44809 | C40: 44810 | D40: 39 | E40: month | F40: Yes
A41: 127604200 | B41: 44809 | C41: 44840 | D41: 39 | E41: month | F41: Yes
A42: 154913576 | B42: 44809 | C42: 44998 | D42: 39 | E42: month | F42: Yes
A43: 154910432 | B43: 44809 | C43: 44998 | D43: 39 | E43: month | F43: Yes
A44: 154911229 | B44: 44809 | C44: 44997 | D44: 39 | E44: month | F44: Yes
...

Sheet cleanup
B3: Customer ID | C3: Created Date | D3: Canceled Date | E3: Subscription Cost | F3: Subscription Interval | G3: Was Subscription Paid
B4: =in!A2 -> 154536156 | C4: =in!B2 -> 44805 | D4: =IF(in!C3="","",in!C3) -> 44806 | E4: =in!D2 -> 39 | F4: =in!E2 -> month | G4: =in!F2 -> Yes
B5: =in!A3 -> 149713408 | C5: =in!B3 -> 44805 | D5: =IF(in!C4="","",in!C4) -> 44806 | E5: =in!D3 -> 39 | F5: =in!E3 -> month | G5: =in!F3 -> No
B6: =in!A4 -> 153756284 | C6: =in!B4 -> 44805 | D6: =IF(in!C5="","",in!C5) -> 44827 | E6: =in!D4 -> 39 | F6: =in!E4 -> month | G6: =in!F4 -> No
B7: =in!A5 -> 121253113 | C7: =in!B5 -> 44805 | D7: =IF(in!C6="","",in!C6) -> 45106 | E7: =in!D5 -> 39 | F7: =in!E5 -> month | G7: =in!F5 -> Yes
B8: =in!A6 -> 154467210 | C8: =in!B6 -> 44805 | D8: =IF(in!C7="","",in!C7) -> 45054 | E8: =in!D6 -> 39 | F8: =in!E6 -> month | G8: =in!F6 -> Yes
B9: =in!A7 -> 154510811 | C9: =in!B7 -> 44805 | D9: =IF(in!C8="","",in!C8) -> 44891 | E9: =in!D7 -> 39 | F9: =in!E7 -> month | G9: =in!F7 -> Yes
B10: =in!A8 -> 154494346 | C10: =in!B8 -> 44805 | D10: =IF(in!C9="","",in!C9) -> 44888 | E10: =in!D8 -> 39 | F10: =in!E8 -> month | G10: =in!F8 -> Yes
B11: =in!A9 -> 148671505 | C11: =in!B9 -> 44805 | D11: =IF(in!C10="","",in!C10) -> 44859 | E11: =in!D9 -> 39 | F11: =in!E9 -> month | G11: =in!F9 -> Yes
B12: =in!A10 -> 154568379 | C12: =in!B10 -> 44805 | D12: =IF(in!C11="","",in!C11) -> 44865 | E12: =in!D10 -> 39 | F12: =in!E10 -> month | G12: =in!F10 -> Yes
B13: =in!A11 -> 154428434 | C13: =in!B11 -> 44805 | D13: =IF(in!C12="","",in!C12) -> 44830 | E13: =in!D11 -> 39 | F13: =in!E11 -> month | G13: =in!F11 -> Yes
B14: =in!A12 -> 154601651 | C14: =in!B12 -> 44805 | D14: =IF(in!C13="","",in!C13) -> 44819 | E14: =in!D12 -> 39 | F14: =in!E12 -> month | G14: =in!F12 -> Yes
B15: =in!A13 -> 122824692 | C15: =in!B13 -> 44805 | D15: =IF(in!C14="","",in!C14) | E15: =in!D13 -> 39 | F15: =in!E13 -> month | G15: =in!F13 -> Yes
... B3072: =in!A3070 -> 188354637 | C3072: =in!B3070 -> 45177 | D3072: =IF(in!C3071="","",in!C3071) | E3072: =in!D3070 -> 39 | F3072: =in!E3070 -> month | G3072: =in!F3070 -> Yes
